<?xml version="1.0" encoding="utf-8"?>

<robot
  name="claw">
  
  <link name="world"/>
  
  <link
    name="base_link">
    <inertial>
      <origin
        xyz="-1.57328618926919E-16 1.27659406015648E-16 -0.00380475448480049"
        rpy="0 0 0" />
      <mass
        value="14.2315320588481" />
      <inertia
        ixx="0.147608042754936"
        ixy="4.93667272888974E-16"
        ixz="-6.23719916937828E-17"
        iyy="0.147608042754937"
        iyz="1.15095319316312E-17"
        izz="0.226294089634963" />
    </inertial>
    <visual>
      <origin
        xyz="0 0 0"
        rpy="0 0 0" />
      <geometry>
        <mesh
          filename="package://robots/meshes/claw/base_link.STL" />
      </geometry>
      <material
        name="">
        <color
          rgba="0.647058823529412 0.619607843137255 0.588235294117647 1" />
      </material>
    </visual>
    <collision>
      <origin
        xyz="0 0 0"
        rpy="0 0 0" />
      <geometry>
        <mesh
          filename="package://robots/meshes/claw/base_link.STL" />
      </geometry>
    </collision>
  </link>
  
  <joint name="fixed" type="fixed">
	<parent link="world"/>
	<child link="base_link"/>  
  </joint>
  
  <link
    name="finger_a">
    <inertial>
      <origin
        xyz="0.05746 -0.11113 5.3429E-16"
        rpy="0 0 0" />
      <mass
        value="5.838" />
      <inertia
        ixx="0.040951"
        ixy="0.0091749"
        ixz="-1.3878E-17"
        iyy="0.010201"
        iyz="6.6163E-17"
        izz="0.049499" />
    </inertial>
    <visual>
      <origin
        xyz="0 0 0"
        rpy="0 0 0" />
      <geometry>
        <mesh
          filename="package://robots/meshes/claw/finger_a.STL" />
      </geometry>
      <material
        name="">
        <color
          rgba="0.64706 0.61961 0.58824 1" />
      </material>
    </visual>
    <collision>
      <origin
        xyz="0 0 0"
        rpy="0 0 0" />
      <geometry>
        <mesh
          filename="package://robots/meshes/claw/finger_a.STL" />
      </geometry>
    </collision>
  </link>
  
  <joint
    name="finger_a_joint"
    type="revolute">
    <origin
      xyz="-0.15588 -0.09 -0.15"
      rpy="1.5708 0.01598 0.5236" />
    <parent
      link="base_link" />
    <child
      link="finger_a" />
    <axis
      xyz="0 0 1" />
    <limit
      lower="-1.5708"
      upper="0.15"
      effort="30"
      velocity="1" />
    <mimic
      joint="rod_joint"
      multiplier="9.28356454545"
      offset="0" />
  </joint>
  
  <link
    name="finger_b">
    <inertial>
      <origin
        xyz="0.05746 -0.11113 -2.4286E-15"
        rpy="0 0 0" />
      <mass
        value="5.838" />
      <inertia
        ixx="0.040951"
        ixy="0.0091749"
        ixz="-3.4694E-18"
        iyy="0.010201"
        iyz="1.4908E-17"
        izz="0.049499" />
    </inertial>
    <visual>
      <origin
        xyz="0 0 0"
        rpy="0 0 0" />
      <geometry>
        <mesh
          filename="package://robots/meshes/claw/finger_b.STL" />
      </geometry>
      <material
        name="">
        <color
          rgba="0.64706 0.61961 0.58824 1" />
      </material>
    </visual>
    <collision>
      <origin
        xyz="0 0 0"
        rpy="0 0 0" />
      <geometry>
        <mesh
          filename="package://robots/meshes/claw/finger_b.STL" />
      </geometry>
    </collision>
  </link>
  
  <joint
    name="finger_b_joint"
    type="revolute">
    <origin
      xyz="0.15588 -0.09 -0.15"
      rpy="1.5708 0.01598 2.618" />
    <parent
      link="base_link" />
    <child
      link="finger_b" />
    <axis
      xyz="0 0 1" />
    <limit
      lower="-1.5708"
      upper="0.15"
      effort="30"
      velocity="1" />
    <mimic
      joint="rod_joint"
      multiplier="9.28356454545"
      offset="0" />
  </joint>
  
  <link
    name="finger_c">
    <inertial>
      <origin
        xyz="0.05746 -0.11113 -7.0719E-18"
        rpy="0 0 0" />
      <mass
        value="5.838" />
      <inertia
        ixx="0.040951"
        ixy="0.0091749"
        ixz="-3.6834E-19"
        iyy="0.010201"
        iyz="-2.2745E-19"
        izz="0.049499" />
    </inertial>
    <visual>
      <origin
        xyz="0 0 0"
        rpy="0 0 0" />
      <geometry>
        <mesh
          filename="package://robots/meshes/claw/finger_c.STL" />
      </geometry>
      <material
        name="">
        <color
          rgba="0.64706 0.61961 0.58824 1" />
      </material>
    </visual>
    <collision>
      <origin
        xyz="0 0 0"
        rpy="0 0 0" />
      <geometry>
        <mesh
          filename="package://robots/meshes/claw/finger_c.STL" />
      </geometry>
    </collision>
  </link>
  
  <joint
    name="finger_c_joint"
    type="revolute">
    <origin
      xyz="0 0.18 -0.15"
      rpy="1.5708 0.01598 -1.5708" />
    <parent
      link="base_link" />
    <child
      link="finger_c" />
    <axis
      xyz="0 0 1" />
    <limit
      lower="-1.5708"
      upper="0.15"
      effort="30"
      velocity="1" />
    <mimic
      joint="rod_joint"
      multiplier="9.28356454545"
      offset="0" />
  </joint>
  
  <link
    name="rod">
    <inertial>
      <origin
        xyz="0 0 0"
        rpy="0 0 0" />
      <mass
        value="0" />
      <inertia
        ixx="0"
        ixy="0"
        ixz="0"
        iyy="0"
        iyz="0"
        izz="0" />
    </inertial>
    <visual>
      <origin
        xyz="0 0 0"
        rpy="0 0 0" />
      <geometry>
        <mesh
          filename="package://robots/meshes/claw/rod.STL" />
      </geometry>
      <material
        name="">
        <color
          rgba="1 1 1 1" />
      </material>
    </visual>
    <collision>
      <origin
        xyz="0 0 0"
        rpy="0 0 0" />
      <geometry>
        <mesh
          filename="package://robots/meshes/claw/rod.STL" />
      </geometry>
    </collision>
  </link>
  
  <joint
    name="rod_joint"
    type="prismatic">
    <origin
      xyz="0 0 0"
      rpy="1.5708 0 0" />
    <parent
      link="base_link" />
    <child
      link="rod" />
    <axis
      xyz="0 1 0" />
    <limit
      lower="0.00"
      upper="-0.11"
      effort="30"
      velocity="1" />
  </joint>
  
  <link
    name="moving_base">
    <inertial>
      <origin
        xyz="1.0298E-15 0.041745 -5.0073E-16"
        rpy="0 0 0" />
      <mass
        value="3.4745" />
      <inertia
        ixx="0.0067165"
        ixy="2.931E-19"
        ixz="3.1841E-17"
        iyy="0.012516"
        iyz="2.2166E-19"
        izz="0.0067165" />
    </inertial>
    <visual>
      <origin
        xyz="0 0 0"
        rpy="0 0 0" />
      <geometry>
        <mesh
          filename="package://robots/meshes/claw/moving_base.STL" />
      </geometry>
      <material
        name="">
        <color
          rgba="0.64706 0.61961 0.58824 1" />
      </material>
    </visual>
    <collision>
      <origin
        xyz="0 0 0"
        rpy="0 0 0" />
      <geometry>
        <mesh
          filename="package://robots/meshes/claw/moving_base.STL" />
      </geometry>
    </collision>
  </link>
  
  <joint
    name="moving_base_joint"
    type="fixed">
    <origin
      xyz="0 -0.109328458561404 0"
      rpy="0 0 0" />
    <parent
      link="rod" />
    <child
      link="moving_base" />
    <axis
      xyz="0 0 0" />
  </joint>
 
  <link
    name="finger_a_support">
    <inertial>
      <origin
        xyz="0.015913 0.031888 0.020735"
        rpy="0 0 0" />
      <mass
        value="0.46607" />
      <inertia
        ixx="0.00032347"
        ixy="-0.00015408"
        ixz="-6.6582E-05"
        iyy="0.00018484"
        iyz="-8.8957E-05"
        izz="0.00040036" />
    </inertial>
    <visual>
      <origin
        xyz="0 0 0"
        rpy="0 0 0" />
      <geometry>
        <mesh
          filename="package://robots/meshes/claw/finger_a_support.STL" />
      </geometry>
      <material
        name="">
        <color
          rgba="0.64706 0.61961 0.58824 1" />
      </material>
    </visual>
    <collision>
      <origin
        xyz="0 0 0"
        rpy="0 0 0" />
      <geometry>
        <mesh
          filename="package://robots/meshes/claw/finger_a_support.STL" />
      </geometry>
    </collision>
  </link>
  
  <joint
    name="finger_a_support_joint"
    type="revolute">
    <origin
      xyz="-0.081292 0.041745 0.058481"
      rpy="3.1416 0 0" />
    <parent
      link="moving_base" />
    <child
      link="finger_a_support" />
    <axis
      xyz="0.5 0 -0.86603" />
    <limit
      lower="-6.14"
      upper="3.14"
      effort="30"
      velocity="1" />
    <mimic
      joint="rod_joint"
      multiplier="12"
      offset="0" />
  </joint>
  
  <link
    name="finger_b_support">
    <inertial>
      <origin
        xyz="0.025913 0.031888 -0.0034141"
        rpy="0 0 0" />
      <mass
        value="0.46607" />
      <inertia
        ixx="0.00032347"
        ixy="-0.00015408"
        ixz="6.6582E-05"
        iyy="0.00018484"
        iyz="8.8957E-05"
        izz="0.00040036" />
    </inertial>
    <visual>
      <origin
        xyz="0 0 0"
        rpy="0 0 0" />
      <geometry>
        <mesh
          filename="package://robots/meshes/claw/finger_b_support.STL" />
      </geometry>
      <material
        name="">
        <color
          rgba="0.64706 0.61961 0.58824 1" />
      </material>
    </visual>
    <collision>
      <origin
        xyz="0 0 0"
        rpy="0 0 0" />
      <geometry>
        <mesh
          filename="package://robots/meshes/claw/finger_b_support.STL" />
      </geometry>
    </collision>
  </link>
  
  <joint
    name="finger_b_support_joint"
    type="revolute">
    <origin
      xyz="0.091292 0.041745 0.04116"
      rpy="0 0 -3.1416" />
    <parent
      link="moving_base" />
    <child
      link="finger_b_support" />
    <axis
      xyz="-0.5 0 -0.86603" />
	<limit
      lower="-6.14"
      upper="6.14"
      effort="30"
      velocity="1" />
      <mimic
      joint="rod_joint"
      multiplier="12"
      offset="0" />
  </joint>
  
  <link
    name="finger_c_support">
    <inertial>
      <origin
        xyz="0.01 -0.031888 0.024149"
        rpy="0 0 0" />
      <mass
        value="0.46607" />
      <inertia
        ixx="0.0004388"
        ixy="-4.1141E-19"
        ixz="3.1913E-19"
        iyy="0.00018484"
        iyz="0.00017791"
        izz="0.00028503" />
    </inertial>
    <visual>
      <origin
        xyz="0 0 0"
        rpy="0 0 0" />
      <geometry>
        <mesh
          filename="package://robots/meshes/claw/finger_c_support.STL" />
      </geometry>
      <material
        name="">
        <color
          rgba="0.64706 0.61961 0.58824 1" />
      </material>
    </visual>
    <collision>
      <origin
        xyz="0 0 0"
        rpy="0 0 0" />
      <geometry>
        <mesh
          filename="package://robots/meshes/claw/finger_c_support.STL" />
      </geometry>
    </collision>
  </link>
  
  <joint
    name="finger_c_support_joint"
    type="revolute">
    <origin
      xyz="-0.01 0.041745 -0.099641"
      rpy="0 0 0" />
    <parent
      link="moving_base" />
    <child
      link="finger_c_support" />
    <axis
      xyz="-1 0 0" />
    <limit
      lower="-6.14"
      upper="6.14"
      effort="30"
      velocity="1" />
      <mimic
      joint="rod_joint"
      multiplier="12"
      offset="0" />
  </joint>
  
  
</robot>
